<?xml version="1.0" encoding="utf-8"?>
<!-- This URDF was automatically created by SolidWorks to URDF Exporter! Originally created by Stephen Brawner (brawner@gmail.com)
     Commit Version: 1.6.0-1-g15f4949  Build Version: 1.6.7594.29634
     For more information, please see http://wiki.ros.org/sw_urdf_exporter -->
<robot name="coach_nanny_robot">
  <link name="base_link">
    <inertial>
      <origin xyz="0.0238969108524964 0.0064934223239613 0.20470967877878" rpy="0 0 0" />
      <mass value="26.1616258468403" />
      <inertia ixx="0.513743502176987" ixy="2.06390204030682E-05" ixz="-6.60339277193219E-07" iyy="0.519407745009906" iyz="7.56228723385907E-07" izz="0.903442693992377" />
    </inertial>
    <visual>
      <origin xyz="0 0 0" rpy="0 0 0" />
      <geometry>
        <mesh filename="package://nanny_description/meshes/base_link.STL" />
      </geometry>
      <material name="">
        <color rgba="0.647058823529412 0.619607843137255 0.588235294117647 1" />
      </material>
    </visual>
    <collision>
      <origin xyz="0 0 0" rpy="0 0 0" />
      <geometry>
        <mesh filename="package://nanny_description/meshes/base_link.STL" />
      </geometry>
    </collision>
  </link>
  <link name="right_wheel">
    <inertial>
      <origin xyz="2.35244231702736E-06 -0.00285205665217148 -2.76396645205318E-06" rpy="0 0 0" />
      <mass value="0.844079114777032" />
      <inertia ixx="0.00130632522786826" ixy="1.96746275377505E-09" ixz="-1.02935065598183E-07" iyy="0.00241733989203521" iyz="-3.47791699410318E-09" izz="0.00130617833749495" />
    </inertial>
    <visual>
      <origin xyz="0 0 0" rpy="0 0 0" />
      <geometry>
        <mesh filename="package://nanny_description/meshes/right_wheel.STL" />
      </geometry>
      <material name="">
        <color rgba="0.298039215686275 0.298039215686275 0.298039215686275 1" />
      </material>
    </visual>
    <collision>
      <origin xyz="0 0 0" rpy="1.54 0 0" />
      <geometry>
        <cylinder radius="0.08" length="0.03175"/>
      </geometry>
    </collision>
  </link>
  <joint name="base_link_right_wheel" type="continuous">
    <origin xyz="0.17336 -0.27871 0.048701" rpy="0 0 0" />
    <parent link="base_link" />
    <child link="right_wheel" />
    <axis xyz="0 1 0" />
  </joint>
  <link name="left_wheel">
    <inertial>
      <origin xyz="-2.35244231702736E-06 0.00285205665217148 -2.7639664520393E-06" rpy="0 0 0" />
      <mass value="0.844079114777031" />
      <inertia ixx="0.00130632522786826" ixy="1.96746275303789E-09" ixz="1.02935065598115E-07" iyy="0.0024173398920352" iyz="3.47791699410444E-09" izz="0.00130617833749495" />
    </inertial>
    <visual>
      <origin xyz="0 0 0" rpy="0 0 0" />
      <geometry>
        <mesh filename="package://nanny_description/meshes/left_wheel.STL" />
      </geometry>
      <material name="">
        <color rgba="0.666666666666667 0.698039215686274 0.768627450980392 1" />
      </material>
    </visual>
    <collision>
      <origin xyz="0 0 0" rpy="-1.54 0 0" />
      <geometry>
        <cylinder radius="0.08" length="0.03175"/>
      </geometry>
    </collision>
  </link>
  <joint name="base_link_left_wheel" type="continuous">
    <origin xyz="0.173356333637394 0.27870625 0.0487011859215695" rpy="0 0 0" />
    <parent link="base_link" />
    <child link="left_wheel" />
    <axis xyz="0 1 0" />
  </joint>
  <link name="right_swivel">
    <inertial>
      <origin xyz="-0.0107952142667258 0.000480178041647072 -0.0226672825074409" rpy="0 0 0" />
      <mass value="1.62791183303881" />
      <inertia ixx="0.00221717689141458" ixy="-6.43720832210226E-12" ixz="-0.000516741659274806" iyy="0.00198478866521882" iyz="-9.79370947643036E-13" izz="0.00236896166493278" />
    </inertial>
    <visual>
      <origin xyz="0 0 0" rpy="0 0 0" />
      <geometry>
        <mesh filename="package://nanny_description/meshes/right_swivel.STL" />
      </geometry>
      <material name="">
        <color rgba="0.647058823529412 0.619607843137255 0.588235294117647 1" />
      </material>
    </visual>
    <collision>
      <origin xyz="0 0 0" rpy="0 0 0" />
      <geometry>
        <mesh filename="package://nanny_description/meshes/right_swivel.STL" />
      </geometry>
    </collision>
  </link>
  <joint name="base_link_right_swivel" type="continuous">
    <origin xyz="-0.1984 -0.1964315 0.0925375" rpy="0 0 0" />
    <parent link="base_link" />
    <child link="right_swivel" />
    <axis xyz="0 0 1" />
  </joint>
  <link name="right_caster">
    <inertial>
      <origin xyz="0 0.000508000000000036 -1.04083408558608E-17" rpy="0 0 0" />
      <mass value="0.470013684691794" />
      <inertia ixx="0.000378325445284186" ixy="5.93554510947243E-21" ixz="1.06710901829001E-20" iyy="0.000538891371757401" iyz="-4.2308434748141E-21" izz="0.000378325445284186" />
    </inertial>
    <visual>
      <origin xyz="0 0 0" rpy="0 0 0" />
      <geometry>
        <mesh filename="package://nanny_description/meshes/right_caster.STL" />
      </geometry>
      <material name="">
        <color rgba="0.298039215686275 0.298039215686275 0.298039215686275 1" />
      </material>
    </visual>
    <collision>
      <origin xyz="0 0 0" rpy="0 0 0" />
      <geometry>
        <mesh filename="package://nanny_description/meshes/right_caster.STL" />
      </geometry>
    </collision>
  </link>
  <joint name="right_swivel_right_caster" type="continuous">
    <origin xyz="-0.04445 -0.000508000000000036 -0.0714375" rpy="0 0 0" />
    <parent link="right_swivel" />
    <child link="right_caster" />
    <axis xyz="0 1 0" />
  </joint>
  <link name="left_swivel">
    <inertial>
      <origin xyz="-0.0107952142667258 0.000480178041647072 -0.0226672825074409" rpy="0 0 0" />
      <mass value="1.62791183303881" />
      <inertia ixx="0.00221717689141458" ixy="-6.43720825937566E-12" ixz="-0.000516741659274806" iyy="0.00198478866521882" iyz="-9.79371026844606E-13" izz="0.00236896166493278" />
    </inertial>
    <visual>
      <origin xyz="0 0 0" rpy="0 0 0" />
      <geometry>
        <mesh filename="package://nanny_description/meshes/left_swivel.STL" />
      </geometry>
      <material name="">
        <color rgba="0.647058823529412 0.619607843137255 0.588235294117647 1" />
      </material>
    </visual>
    <collision>
      <origin xyz="0 0 0" rpy="0 0 0" />
      <geometry>
        <mesh filename="package://nanny_description/meshes/left_swivel.STL" />
      </geometry>
    </collision>
  </link>
  <joint name="base_link_left_swivel" type="continuous">
    <origin xyz="-0.1984 0.1964315 0.0925375" rpy="0 0 0" />
    <parent link="base_link" />
    <child link="left_swivel" />
    <axis xyz="0 0 1" />
  </joint>
  <link name="left_caster">
    <inertial>
      <origin xyz="0 0.000507999999999981 0" rpy="0 0 0" />
      <mass value="0.470013684691794" />
      <inertia ixx="0.000378325445284186" ixy="3.61830274228318E-21" ixz="1.06710901829001E-20" iyy="0.000538891371757401" iyz="-5.17645714725962E-21" izz="0.000378325445284186" />
    </inertial>
    <visual>
      <origin xyz="0 0 0" rpy="0 0 0" />
      <geometry>
        <mesh filename="package://nanny_description/meshes/left_caster.STL" />
      </geometry>
      <material name="">
        <color rgba="0.298039215686275 0.298039215686275 0.298039215686275 1" />
      </material>
    </visual>
    <collision>
      <origin xyz="0 0 0" rpy="0 0 0" />
      <geometry>
        <mesh filename="package://nanny_description/meshes/left_caster.STL" />
      </geometry>
    </collision>
  </link>
  <joint name="left_swivel_left_caster" type="continuous">
    <origin xyz="-0.04445 -0.000507999999999981 -0.0714375" rpy="0 0 0" />
    <parent link="left_swivel" />
    <child link="left_caster" />
    <axis xyz="0 -1 0" />
  </joint>
  <link name="front_laser">
    <inertial>
      <mass value="1e-5" />
      <origin xyz="0 0 0" rpy="0 0 0"/>
      <inertia ixx="1e-6" ixy="0" ixz="0" iyy="1e-6" iyz="0" izz="1e-6" />
    </inertial>
    <visual>
      <origin xyz="0 0 0" rpy="0 0 0" />
      <geometry>
        <mesh filename="package://nanny_description/meshes/front_laser.STL" />
      </geometry>
      <material name="">
        <color rgba="0.89804 0.91765 0.92941 1" />
      </material>
    </visual>
    <collision>
      <origin xyz="0 0 0" rpy="0 0 0" />
      <geometry>
        <mesh filename="package://nanny_description/meshes/front_laser.STL" />
      </geometry>
    </collision>
  </link>
  <joint name="base_link_front_laser" type="revolute">
    <origin xyz="0.26865 0 0.043175" rpy="0 0 0" />
    <parent link="base_link" />
    <child link="front_laser" />
    <axis xyz="0 0 1" />
    <limit lower="0" upper="0" effort="0" velocity="0" />
  </joint>
  <link name="rear_laser">
    <inertial>
      <mass value="1e-5" />
      <origin xyz="0 0 0" rpy="0 0 0"/>
      <inertia ixx="1e-6" ixy="0" ixz="0" iyy="1e-6" iyz="0" izz="1e-6" />
    </inertial>
    <visual>
      <origin xyz="0 0 0" rpy="0 0 0" />
      <geometry>
        <mesh filename="package://nanny_description/meshes/rear_laser.STL" />
      </geometry>
      <material name="">
        <color rgba="0.89804 0.91765 0.92941 1" />
      </material>
    </visual>
    <collision>
      <origin xyz="0 0 0" rpy="0 0 0" />
      <geometry>
        <mesh filename="package://nanny_description/meshes/rear_laser.STL" />
      </geometry>
    </collision>
  </link>
  <joint name="base_link_rear_laser" type="revolute">
    <origin xyz="-0.27182 0 0.043175" rpy="0 0 0" />
    <parent link="base_link" />
    <child link="rear_laser" />
    <axis xyz="0 0 1" />
    <limit lower="0" upper="0" effort="0" velocity="0" />
  </joint>

  <transmission name="right_wheel_trans">
    <type>transmission_interface/SimpleTransmission</type>
    <actuator name="right_wheel_motor">
      <mechanicalReduction>1</mechanicalReduction>
    </actuator>
    <joint name="base_link_right_wheel">
      <hardwareInterface>hardware_interface/VelocityJointInterface</hardwareInterface>
    </joint>
  </transmission>

  <transmission name="left_wheel_trans">
    <type>transmission_interface/SimpleTransmission</type>
    <actuator name="left_wheel_motor">
      <mechanicalReduction>1</mechanicalReduction>
    </actuator>
    <joint name="base_link_left_wheel">
      <hardwareInterface>hardware_interface/VelocityJointInterface</hardwareInterface>
    </joint>
  </transmission>

  <gazebo reference="front_laser">
    <sensor type="gpu_ray" name="head_hokuyo_sensor">
      <pose>0 0 0 0 0 0</pose>
      <visualize>true</visualize>
      <update_rate>40</update_rate>
      <ray>
        <scan>
          <horizontal>
            <samples>180</samples>
            <resolution>1</resolution>
            <min_angle>-1.570796</min_angle>
            <max_angle>1.570796</max_angle>
          </horizontal>
        </scan>
        <range>
          <min>0.10</min>
          <max>40</max>
          <resolution>0.01</resolution>
        </range>
        <noise>
          <type>gaussian</type>
          <!-- Noise parameters based on published spec for Hokuyo laser
               achieving "+-30mm" accuracy at range < 10m.  A mean of 0.0m and
               stddev of 0.01m will put 99.7% of samples within 0.03m of the true
               reading. -->
          <mean>0.0</mean>
          <stddev>0.01</stddev>
        </noise>
      </ray>
      <plugin name="gazebo_ros_head_hokuyo_controller" filename="libgazebo_ros_gpu_laser.so">
        <topicName>/front_laser_scan</topicName>
        <frameName>odom</frameName>
      </plugin>
    </sensor>
  </gazebo>

  <gazebo>
    <plugin name="gazebo_ros_control" filename="libgazebo_ros_control.so">
      <robotNamespace>/</robotNamespace>
    </plugin>
  </gazebo>

</robot>