<?xml version="1.0" encoding="utf-8"?>
<!-- This URDF was automatically created by SolidWorks to URDF Exporter! Originally created by Stephen Brawner (brawner@gmail.com) 
     Commit Version: 1.6.0-1-g15f4949  Build Version: 1.6.7594.29634
     For more information, please see http://wiki.ros.org/sw_urdf_exporter -->
<robot
  name="covid_killer_robot" xmlns:xacro="http://www.ros.org/wiki/xacro">
  <xacro:include filename="$(find nanny_description)/urdf/_d435.urdf.xacro" />
  
 <link
    name="base_link">
    <inertial>
      <origin
        xyz="-1.06551968085109E-10 -8.06828802844026E-07 0.234819567511574"
        rpy="0 0 1.57" />
      <mass
        value="44.766149285195" />
      <inertia
        ixx="1.66396255387404"
        ixy="3.50880461801341E-08"
        ixz="8.83078687148099E-18"
        iyy="1.77002354702262"
        iyz="1.11058889198517E-10"
        izz="2.8664237727839" />
    </inertial>
    <visual>
      <origin
        xyz="0 0 0"
        rpy="0 0 1.57" />
      <geometry>
        <mesh
          filename="package://nanny_description/meshes/base_link.STL" />
      </geometry>
      <material
        name="">
        <color
          rgba="0.549019607843137 0.180392156862745 0.180392156862745 1" />
      </material>
    </visual>
    <collision>
      <origin
        xyz="0 0 0"
        rpy="0 0 1.57" />
      <geometry>
        <mesh
          filename="package://nanny_description/meshes/base_link.STL" />
      </geometry>
    </collision>
  </link>
  <link
    name="front_right_swivel">
    <inertial>
      <origin
        xyz="-0.010539 -0.00043158 -0.022295"
        rpy="0 0 0" />
      <mass
        value="1.5935" />
      <inertia
        ixx="0.002136"
        ixy="-3.0746E-12"
        ixz="-0.00048606"
        iyy="0.0019069"
        iyz="-1.007E-12"
        izz="0.0023037" />
    </inertial>
    <visual>
      <origin
        xyz="0 0 0"
        rpy="0 0 0" />
      <geometry>
        <mesh
          filename="package://nanny_description/meshes/front_right_swivel.STL" />
      </geometry>
      <material
        name="">
        <color
          rgba="0.2 0.2 0.2 1" />
      </material>
    </visual>
    <collision>
      <origin
        xyz="0 0 0"
        rpy="0 0 0" />
      <geometry>
        <mesh
          filename="package://nanny_description/meshes/front_right_swivel.STL" />
      </geometry>
    </collision>
  </link>
  <joint
    name="base_link_front_right_swivel"
    type="continuous">
    <origin
      xyz="0.254 -0.254 0.092538"
      rpy="0 0 0" />
    <parent
      link="base_link" />
    <child
      link="front_right_swivel" />
    <axis
      xyz="0 0 1" />
  </joint>
  <link
    name="front_right_caster">
    <inertial>
      <origin
        xyz="2.7756E-17 -5.5511E-17 3.4694E-18"
        rpy="0 0 0" />
      <mass
        value="0.44299" />
      <inertia
        ixx="0.0003631"
        ixy="-1.2519E-18"
        ixz="-6.1347E-21"
        iyy="0.00054249"
        iyz="-1.8775E-21"
        izz="0.0003631" />
    </inertial>
    <visual>
      <origin
        xyz="0 0 0"
        rpy="0 0 0" />
      <geometry>
        <mesh
          filename="package://nanny_description/meshes/front_right_caster.STL" />
      </geometry>
      <material
        name="">
        <color
          rgba="0.29804 0.29804 0.29804 1" />
      </material>
    </visual>
    <collision>
      <origin
        xyz="0 0 0"
        rpy="0 0 0" />
      <geometry>
        <mesh
          filename="package://nanny_description/meshes/front_right_caster.STL" />
      </geometry>
    </collision>
  </link>
  <joint
    name="front_right_swivel_front_right_caster"
    type="continuous">
    <origin
      xyz="-0.04445 0 -0.071438"
      rpy="0 0 0" />
    <parent
      link="front_right_swivel" />
    <child
      link="front_right_caster" />
    <axis
      xyz="0 1 0" />
  </joint>
  <link
    name="right_wheel">
    <inertial>
      <origin
        xyz="2.3524E-06 -0.0028521 -2.764E-06"
        rpy="0 0 0" />
      <mass
        value="0.84408" />
      <inertia
        ixx="0.0013063"
        ixy="1.9675E-09"
        ixz="-1.0294E-07"
        iyy="0.0024173"
        iyz="-3.4779E-09"
        izz="0.0013062" />
    </inertial>
    <visual>
      <origin
        xyz="0 0 0"
        rpy="0 0 0" />
      <geometry>
        <mesh
          filename="package://nanny_description/meshes/right_wheel.STL" />
      </geometry>
      <material
        name="">
        <color
          rgba="0.29804 0.29804 0.29804 1" />
      </material>
    </visual>
    <collision>
      <origin xyz="0 0 0" rpy="1.57 0 0" />
      <geometry>
        <cylinder radius="0.08" length="0.03175"/>
      </geometry>
    </collision>
  </link>
  <joint
    name="base_link_right_wheel"
    type="continuous">
    <origin
      xyz="0 -0.28302 0.048701"
      rpy="0 0 0" />
    <parent
      link="base_link" />
    <child
      link="right_wheel" />
    <axis
      xyz="0 1 0" />
<limit effort="10000" velocity="1000"/>
	<joint_properties damping="1.0" friction="1.0"/>
  </joint>
  <link
    name="back_right_swivel">
    <inertial>
      <origin
        xyz="-0.010539 -0.00043158 -0.022295"
        rpy="0 0 0" />
      <mass
        value="1.5935" />
      <inertia
        ixx="0.002136"
        ixy="-3.0746E-12"
        ixz="-0.00048606"
        iyy="0.0019069"
        iyz="-1.007E-12"
        izz="0.0023037" />
    </inertial>
    <visual>
      <origin
        xyz="0 0 0"
        rpy="0 0 0" />
      <geometry>
        <mesh
          filename="package://nanny_description/meshes/back_right_swivel.STL" />
      </geometry>
      <material
        name="">
        <color
          rgba="0.2 0.2 0.2 1" />
      </material>
    </visual>
    <collision>
      <origin
        xyz="0 0 0"
        rpy="0 0 0" />
      <geometry>
        <mesh
          filename="package://nanny_description/meshes/back_right_swivel.STL" />
      </geometry>
    </collision>
  </link>
  <joint
    name="base_link_back_right_swivel"
    type="continuous">
    <origin
      xyz="-0.254 -0.254 0.092538"
      rpy="0 0 0" />
    <parent
      link="base_link" />
    <child
      link="back_right_swivel" />
    <axis
      xyz="0 0 1" />
  </joint>
  <link
    name="back_right_caster">
    <inertial>
      <origin
        xyz="0 0 3.4694E-18"
        rpy="0 0 0" />
      <mass
        value="0.44299" />
      <inertia
        ixx="0.0003631"
        ixy="-1.2874E-18"
        ixz="-1.0192E-20"
        iyy="0.00054249"
        iyz="-3.243E-20"
        izz="0.0003631" />
    </inertial>
    <visual>
      <origin
        xyz="0 0 0"
        rpy="0 0 0" />
      <geometry>
        <mesh
          filename="package://nanny_description/meshes/back_right_caster.STL" />
      </geometry>
      <material
        name="">
        <color
          rgba="0.29804 0.29804 0.29804 1" />
      </material>
    </visual>
    <collision>
      <origin
        xyz="0 0 0"
        rpy="0 0 0" />
      <geometry>
        <mesh
          filename="package://nanny_description/meshes/back_right_caster.STL" />
      </geometry>
    </collision>
  </link>
  <joint
    name="back_right_swivel_back_right_caster"
    type="continuous">
    <origin
      xyz="-0.04445 0 -0.071438"
      rpy="0 0 0" />
    <parent
      link="back_right_swivel" />
    <child
      link="back_right_caster" />
    <axis
      xyz="0 -1 0" />
  </joint>
  <link
    name="front_left_swivel">
    <inertial>
      <origin
        xyz="-0.0105385343606004 -0.000431579515207503 -0.0222953198080332"
        rpy="0 0 0" />
      <mass
        value="1.59345861527837" />
      <inertia
        ixx="0.00213604390430319"
        ixy="-3.0746191222679E-12"
        ixz="-0.000486062070883073"
        iyy="0.00190689536966472"
        iyz="-1.00704358920823E-12"
        izz="0.00230366403853992" />
    </inertial>
    <visual>
      <origin
        xyz="0 0 0"
        rpy="0 0 0" />
      <geometry>
        <mesh
          filename="package://nanny_description/meshes/front_left_swivel.STL" />
      </geometry>
      <material
        name="">
        <color
          rgba="0.2 0.2 0.2 1" />
      </material>
    </visual>
    <collision>
      <origin
        xyz="0 0 0"
        rpy="0 0 0" />
      <geometry>
        <mesh
          filename="package://nanny_description/meshes/front_left_swivel.STL" />
      </geometry>
    </collision>
  </link>
  <joint
    name="base_link_front_left_swivel"
    type="continuous">
    <origin
      xyz="0.254 0.254 0.092538"
      rpy="0 0 0" />
    <parent
      link="base_link" />
    <child
      link="front_left_swivel" />
    <axis
      xyz="0 0 1" />
  </joint>
  <link
    name="front_left_caster">
    <inertial>
      <origin
        xyz="2.77555756156289E-17 5.55111512312578E-17 3.46944695195361E-18"
        rpy="0 0 0" />
      <mass
        value="0.442987770505456" />
      <inertia
        ixx="0.000363097660011126"
        ixy="-1.24369920555879E-18"
        ixz="-1.43333606606265E-20"
        iyy="0.000542490473200416"
        iyz="-1.62479589404392E-20"
        izz="0.000363097660011126" />
    </inertial>
    <visual>
      <origin
        xyz="0 0 0"
        rpy="0 0 0" />
      <geometry>
        <mesh
          filename="package://nanny_description/meshes/front_left_caster.STL" />
      </geometry>
      <material
        name="">
        <color
          rgba="0.298039215686275 0.298039215686275 0.298039215686275 1" />
      </material>
    </visual>
    <collision>
      <origin
        xyz="0 0 0"
        rpy="0 0 0" />
      <geometry>
        <mesh
          filename="package://nanny_description/meshes/front_left_caster.STL" />
      </geometry>
    </collision>
  </link>
  <joint
    name="front_left_swivel_front_left_caster"
    type="continuous">
    <origin
      xyz="-0.04445 0 -0.071438"
      rpy="0 0 0" />
    <parent
      link="front_left_swivel" />
    <child
      link="front_left_caster" />
    <axis
      xyz="0 -1 0" />
  </joint>
  <link
    name="left_wheel">
    <inertial>
      <origin
        xyz="-2.35244231706132E-06 0.00285205665217153 -2.76396645204624E-06"
        rpy="0 0 0" />
      <mass
        value="0.84407911477703" />
      <inertia
        ixx="0.00130632522786826"
        ixy="1.96746274935287E-09"
        ixz="1.0293506559815E-07"
        iyy="0.0024173398920352"
        iyz="3.47791699410058E-09"
        izz="0.00130617833749495" />
    </inertial>
    <visual>
      <origin
        xyz="0 0 0"
        rpy="0 0 0" />
      <geometry>
        <mesh
          filename="package://nanny_description/meshes/left_wheel.STL" />
      </geometry>
      <material
        name="">
        <color
          rgba="0.666666666666667 0.698039215686274 0.768627450980392 1" />
      </material>
    </visual>
    <collision>
      <origin xyz="0 0 0" rpy="-1.57 0 0" />
      <geometry>
        <cylinder radius="0.08" length="0.03175"/>
      </geometry>
    </collision>
  </link>
  <joint
    name="base_link_left_wheel"
    type="continuous">
    <origin
      xyz="0 0.28302 0.048701"
      rpy="0 0 0" />
    <parent
      link="base_link" />
    <child
      link="left_wheel" />
    <axis
      xyz="0 1 0" />
<limit effort="10000" velocity="1000"/>
	<joint_properties damping="1.0" friction="1.0"/>
  </joint>
  <link
    name="back_left_swivel">
    <inertial>
      <origin
        xyz="-0.0105385343606004 -0.000431579515207448 -0.0222953198080332"
        rpy="0 0 0" />
      <mass
        value="1.59345861527837" />
      <inertia
        ixx="0.00213604390430319"
        ixy="-3.07461898764287E-12"
        ixz="-0.000486062070883073"
        iyy="0.00190689536966472"
        iyz="-1.00704374440005E-12"
        izz="0.00230366403853992" />
    </inertial>
    <visual>
      <origin
        xyz="0 0 0"
        rpy="0 0 0" />
      <geometry>
        <mesh
          filename="package://nanny_description/meshes/back_left_swivel.STL" />
      </geometry>
      <material
        name="">
        <color
          rgba="0.2 0.2 0.2 1" />
      </material>
    </visual>
    <collision>
      <origin
        xyz="0 0 0"
        rpy="0 0 0" />
      <geometry>
	<mesh
        filename="package://nanny_description/meshes/back_left_swivel.STL" />
      </geometry>
    </collision>
  </link>
  <joint
    name="base_link_back_left_swivel"
    type="continuous">
    <origin
      xyz="-0.254 0.254 0.092538"
      rpy="0 0 0" />
    <parent
      link="base_link" />
    <child
      link="back_left_swivel" />
    <axis
      xyz="0 0 1" />
  </joint>
  <link
    name="back_left_caster">
    <inertial>
      <origin
        xyz="-5.55111512312578E-17 5.55111512312578E-17 6.93889390390723E-18"
        rpy="0 0 0" />
      <mass
        value="0.442987770505456" />
      <inertia
        ixx="0.000363097660011126"
        ixy="-1.28686611370647E-18"
        ixz="-9.16469472235913E-21"
        iyy="0.000542490473200416"
        iyz="-2.70477844640616E-20"
        izz="0.000363097660011126" />
    </inertial>
    <visual>
      <origin
        xyz="0 0 0"
        rpy="0 0 0" />
      <geometry>
        <mesh
          filename="package://nanny_description/meshes/back_left_caster.STL" />
      </geometry>
      <material
        name="">
        <color
          rgba="0.298039215686275 0.298039215686275 0.298039215686275 1" />
      </material>
    </visual>
    <collision>
      <origin
        xyz="0 0 0"
        rpy="0 0 0" />
      <geometry>
        <mesh
          filename="package://nanny_description/meshes/back_left_caster.STL" />
      </geometry>
    </collision>
  </link>
  <joint
    name="back_left_swivel_back_left_caster"
    type="continuous">
    <origin
      xyz="-0.04445 0 -0.071438"
      rpy="0 0 0" />
    <parent
      link="back_left_swivel" />
    <child
      link="back_left_caster" />
    <axis
      xyz="0 -1 0" />
  </joint>

  <link
    name="front_laser">
    <inertial>
      <origin
        xyz="-0.00064881 3.9624E-06 -0.0052873"
        rpy="0 0 0" />
      <mass
        value="0.36783" />
      <inertia
        ixx="9.1717E-05"
        ixy="8.8216E-09"
        ixz="1.2087E-06"
        iyy="9.3129E-05"
        iyz="-3.27E-11"
        izz="0.00012343" />
    </inertial>
    <visual>
      <origin
        xyz="0 0 0"
        rpy="0 0 0" />
      <geometry>
        <mesh
          filename="package://nanny_description/meshes/front_laser.STL" />
      </geometry>
      <material
        name="">
        <color
          rgba="0.89804 0.91765 0.92941 1" />
      </material>
    </visual>
    <collision>
      <origin
        xyz="0 0 0"
        rpy="0 0 0" />
      <geometry>
        <mesh
          filename="package://nanny_description/meshes/front_laser.STL" />
      </geometry>
    </collision>
  </link>
  <joint
    name="base_link_front_laser"
    type="fixed">
    <origin
      xyz="0.38239 0 0.15967"
      rpy="0 0 0" />
    <parent
      link="base_link" />
    <child
      link="front_laser" />
    <axis
      xyz="0 0 1" />
    <limit
      lower="0"
      upper="0"
      effort="0"
      velocity="0" />
  </joint>
<!--

  <link
    name="rear_laser">
    <inertial>
      <origin
        xyz="-0.00064881 3.9624E-06 -0.0052873"
        rpy="0 0 0" />
      <mass
        value="0.36783" />
      <inertia
        ixx="9.1717E-05"
        ixy="8.8216E-09"
        ixz="1.2087E-06"
        iyy="9.3129E-05"
        iyz="-3.27E-11"
        izz="0.00012343" />
    </inertial>
    <visual>
      <origin
        xyz="0 0 0"
        rpy="0 0 0" />
      <geometry>
        <mesh
          filename="package://nanny_description/meshes/front_laser.STL" />
      </geometry>
      <material
        name="">
        <color
          rgba="0.89804 0.91765 0.92941 1" />
      </material>
    </visual>
    <collision>
      <origin
        xyz="0 0 0"
        rpy="0 0 0" />
      <geometry>
        <mesh
          filename="package://nanny_description/meshes/front_laser.STL" />
      </geometry>
    </collision>
  </link>
  <joint
    name="base_link_rear_laser"
    type="revolute">
    <origin
      xyz="0 0.38239 0.15967"
      rpy="0 0 1.5708" />
    <parent
      link="base_link" />
    <child
      link="rear_laser" />
    <axis
      xyz="0 0 -1" />
    <limit
      lower="0"
      upper="0"
      effort="0"
      velocity="0" />
  </joint>
-->
  <transmission name="right_wheel_trans">
    <type>transmission_interface/SimpleTransmission</type>
    <actuator name="right_wheel_motor">
      <mechanicalReduction>1</mechanicalReduction>
    </actuator>
    <joint name="base_link_right_wheel">
      <hardwareInterface>hardware_interface/VelocityJointInterface</hardwareInterface>
	<limit effort="10000" velocity="1000"/>
	<joint_properties damping="1.0" friction="1.0"/>
    </joint>
  </transmission>

  <transmission name="left_wheel_trans">
    <type>transmission_interface/SimpleTransmission</type>
    <actuator name="left_wheel_motor">
      <mechanicalReduction>1</mechanicalReduction>
    </actuator>
    <joint name="base_link_left_wheel">
      <hardwareInterface>hardware_interface/VelocityJointInterface</hardwareInterface>
	<limit effort="10000" velocity="1000"/>
	<joint_properties damping="1.0" friction="1.0"/>
    </joint>
  </transmission>

  <gazebo reference="front_laser">
    <sensor type="ray" name="head_hokuyo_sensor">
      <pose>0 0 0 0 0 0</pose>
      <visualize>true</visualize>
      <update_rate>40</update_rate>
      <ray>
        <scan>
          <horizontal>
            <samples>180</samples>
            <resolution>1</resolution>
            <min_angle>-1.570796</min_angle>
            <max_angle>1.570796</max_angle>
          </horizontal>
        </scan>
        <range>
          <min>0.10</min>
          <max>40</max>
          <resolution>0.01</resolution>
        </range>
        <noise>
          <type>gaussian</type>
       <!--   Noise parameters based on published spec for Hokuyo laser
               achieving "+-30mm" accuracy at range < 10m.  A mean of 0.0m and
               stddev of 0.01m will put 99.7% of samples within 0.03m of the true
               reading.-->
          <mean>0.0</mean>
          <stddev>0.01</stddev>
        </noise>
      </ray>
      <plugin name="gazebo_ros_head_hokuyo_controller" filename="libgazebo_ros_laser.so">
        <topicName>/front_laser_scan</topicName>
        <frameName>odom</frameName>
      </plugin>
    </sensor>
  </gazebo>
<!--
  <gazebo reference="rear_laser">
    <sensor type="ray" name="head_hokuyo_sensor">
      <pose>0 0 0 0 0 0</pose>
      <visualize>false</visualize>
      <update_rate>40</update_rate>
      <ray>
        <scan>
          <horizontal>
            <samples>180</samples>
            <resolution>1</resolution>
            <min_angle>-1.570796</min_angle>
            <max_angle>1.570796</max_angle>
          </horizontal>
        </scan>
        <range>
          <min>0.10</min>
          <max>40</max>
          <resolution>0.01</resolution>
        </range>
        <noise>
          <type>gaussian</type>
         Noise parameters based on published spec for Hokuyo laser
               achieving "+-30mm" accuracy at range < 10m.  A mean of 0.0m and

               stddev of 0.01m will put 99.7% of samples within 0.03m of the true
               reading. 
          <mean>0.0</mean>
          <stddev>0.01</stddev>
        </noise>
      </ray>
      <plugin name="gazebo_ros_head_hokuyo_controller" filename="libgazebo_ros_laser.so">
        <topicName>/rear_laser_scan</topicName>
        <frameName>odom</frameName>
      </plugin>
    </sensor>
  </gazebo>-->
    <xacro:include filename="$(find nanny_description)/urdf/_d435.urdf.xacro"/>
  <sensor_d435 parent="base_link">
    <origin xyz="0.38239 0  0.2" rpy="0 0 0"/>
  </sensor_d435>
   <!--   <sensor_d435 parent="base_link" name="frontCamera" >
    	<origin xyz="0 -0.38239 0.2" rpy="0 0 -1.57079"/>
    </sensor_d435>-->
  <gazebo>
    <plugin name="gazebo_ros_control" filename="libgazebo_ros_control.so">
      <robotNamespace>/</robotNamespace>
    </plugin>
  </gazebo>

</robot>
