<?xml version="1.0" ?>
<robot name="nanny" xmlns:xacro="http://www.ros.org/wiki/xacro">

<xacro:include filename="$(find nanny_description)/urdf/materials.xacro" />
<xacro:include filename="$(find nanny_description)/urdf/nanny.trans" />
<xacro:include filename="$(find nanny_description)/urdf/nanny.gazebo" />

<xacro:property name="cameraSize" value="0.05"/>
<xacro:property name="cameraMass" value="0.1"/>

<link name="dummy"> 
</link> 
<joint name="dummy_joint" type="fixed">
 <parent link="dummy"/>
 <child link="base_link"/> 
</joint>

<link name="base_link">
  <inertial>
    <origin rpy="0 0 0" xyz="0.4999709515803751 -0.14927018860497332 0.005627893204435959"/>
    <mass value="11.175436537973397"/>
    <inertia ixx="0.25996" ixy="-9.5e-05" ixz="0.0" iyy="0.399589" iyz="0.0" izz="0.659248"/>
  </inertial>
  <visual>
    <origin rpy="0 0 0" xyz="0 0 0.021978"/>
    <geometry>
      <mesh filename="package://nanny_description/meshes/base_link.stl" scale="0.001 0.001 0.001"/>
    </geometry>
    <material name="silver"/>
  </visual>
  <collision>
    <origin rpy="0 0 0" xyz="0 0 0.021978"/>
    <geometry>
      <mesh filename="package://nanny_description/meshes/base_link.stl" scale="0.001 0.001 0.001"/>
    </geometry>
  </collision>
</link>

<link name="motor_v1__1__1">
  <inertial>
    <origin rpy="0 0 0" xyz="0.02586757075254814 1.0048361068326628e-05 0.044664692417302816"/>
    <mass value="11.11827564139619"/>
    <inertia ixx="0.013324" ixy="-3.4e-05" ixz="-3.4e-05" iyy="0.040366" iyz="-7e-06" izz="0.04016"/>
  </inertial>
  <visual>
    <origin rpy="0 0 0" xyz="-0.144318 0.27111 0.01"/>
    <geometry>
      <mesh filename="package://nanny_description/meshes/motor_v1__1__1.stl" scale="0.001 0.001 0.001"/>
    </geometry>
    <material name="silver"/>
  </visual>
  <collision>
    <origin rpy="0 0 0" xyz="-0.144318 0.27111 0.01"/>
    <geometry>
      <mesh filename="package://nanny_description/meshes/motor_v1__1__1.stl" scale="0.001 0.001 0.001"/>
    </geometry>
  </collision>
</link>

<link name="motor_v1_1">
  <inertial>
    <origin rpy="0 0 0" xyz="0.019132519213283405 -1.0357512956582493e-05 0.044664692417303135"/>
    <mass value="11.11827564139619"/>
    <inertia ixx="0.013324" ixy="-3.4e-05" ixz="3.4e-05" iyy="0.040366" iyz="7e-06" izz="0.04016"/>
  </inertial>
  <visual>
    <origin rpy="0 0 0" xyz="-0.808518 0.27111 0.01"/>
    <geometry>
      <mesh filename="package://nanny_description/meshes/motor_v1_1.stl" scale="0.001 0.001 0.001"/>
    </geometry>
    <material name="silver"/>
  </visual>
  <collision>
    <origin rpy="0 0 0" xyz="-0.808518 0.27111 0.01"/>
    <geometry>
      <mesh filename="package://nanny_description/meshes/motor_v1_1.stl" scale="0.001 0.001 0.001"/>
    </geometry>
  </collision>
</link>

<link name="wheel_v1__1__1">
  <inertial>
    <origin rpy="0 0 0" xyz="0.01532236191425454 9.571463954721748e-05 -0.00011317034417850091"/>
    <mass value="0.42973723468390157"/>
    <inertia ixx="0.001747" ixy="-0.0" ixz="0.0" iyy="0.000923" iyz="0.0" izz="0.000923"/>
  </inertial>
  <visual>
    <origin rpy="0 0 0" xyz="-0.068818 0.271212 -0.034669"/>
    <geometry>
      <mesh filename="package://nanny_description/meshes/wheel_v1__1__1.stl" scale="0.001 0.001 0.001"/>
    </geometry>
    <material name="silver"/>
  </visual>
  <collision>
    <origin rpy="0 0 0" xyz="-0.068818 0.271212 -0.034669"/>
    <geometry>
      <mesh filename="package://nanny_description/meshes/wheel_v1__1__1.stl" scale="0.001 0.001 0.001"/>
    </geometry>
  </collision>
</link>

<link name="wheel_v1_1">
  <inertial>
    <origin rpy="0 0 0" xyz="-0.01532227194842306 -9.502379143522255e-05 -0.0001131703441781956"/>
    <mass value="0.42973723468390157"/>
    <inertia ixx="0.001747" ixy="-0.0" ixz="-0.0" iyy="0.000923" iyz="-0.0" izz="0.000923"/>
  </inertial>
  <visual>
    <origin rpy="0 0 0" xyz="-0.931018 0.271009 -0.034669"/>
    <geometry>
      <mesh filename="package://nanny_description/meshes/wheel_v1_1.stl" scale="0.001 0.001 0.001"/>
    </geometry>
    <material name="silver"/>
  </visual>
  <collision>
    <origin rpy="0 0 0" xyz="-0.931018 0.271009 -0.034669"/>
    <geometry>
      <mesh filename="package://nanny_description/meshes/wheel_v1_1.stl" scale="0.001 0.001 0.001"/>
    </geometry>
  </collision>
</link>

<link name="extrude_1">
  <inertial>
    <origin rpy="0 0 0" xyz="0.004400038989383126 0.010926590538250985 0.10401739320443476"/>
    <mass value="0.10302216766599791"/>
    <inertia ixx="0.000397" ixy="-0.0" ixz="0.0" iyy="0.000378" iyz="0.0" izz="3.3e-05"/>
  </inertial>
  <visual>
    <origin rpy="0 0 0" xyz="-0.826018 0.094334 0.0227"/>
    <geometry>
      <mesh filename="package://nanny_description/meshes/extrude_1.stl" scale="0.001 0.001 0.001"/>
    </geometry>
    <material name="silver"/>
  </visual>
  <collision>
    <origin rpy="0 0 0" xyz="-0.826018 0.094334 0.01"/>
    <geometry>
      <mesh filename="package://nanny_description/meshes/extrude_1.stl" scale="0.001 0.001 0.001"/>
    </geometry>
  </collision>
</link>

<link name="extrude_2">
  <inertial>
    <origin rpy="0 0 0" xyz="-0.01142996101061719 -0.00832636863072056 0.10401739320443487"/>
    <mass value="0.10302216766599791"/>
    <inertia ixx="0.000397" ixy="-0.0" ixz="0.0" iyy="0.000378" iyz="0.0" izz="3.3e-05"/>
  </inertial>
  <visual>
    <origin rpy="0 0 0" xyz="-0.180818 0.074834 0.01"/>
    <geometry>
      <mesh filename="package://nanny_description/meshes/extrude_2.stl" scale="0.001 0.001 0.001"/>
    </geometry>
    <material name="silver"/>
  </visual>
  <collision>
    <origin rpy="0 0 0" xyz="-0.180818 0.074834 0.01"/>
    <geometry>
      <mesh filename="package://nanny_description/meshes/extrude_2.stl" scale="0.001 0.001 0.001"/>
    </geometry>
  </collision>
</link>

<link name="extrude_3">
  <inertial>
    <origin rpy="0 0 0" xyz="-0.01963652956649553 0.008650098753062774 0.1040173932044348"/>
    <mass value="0.10302216766599791"/>
    <inertia ixx="0.000378" ixy="0.0" ixz="-0.0" iyy="0.000397" iyz="-0.0" izz="3.3e-05"/>
  </inertial>
  <visual>
    <origin rpy="0 0 0" xyz="-0.321318 0.379834 0.01"/>
    <geometry>
      <mesh filename="package://nanny_description/meshes/extrude_3.stl" scale="0.001 0.001 0.001"/>
    </geometry>
    <material name="silver"/>
  </visual>
  <collision>
    <origin rpy="0 0 0" xyz="-0.321318 0.379834 0.01"/>
    <geometry>
      <mesh filename="package://nanny_description/meshes/extrude_3.stl" scale="0.001 0.001 0.001"/>
    </geometry>
  </collision>
</link>

<link name="extrude_4">
  <inertial>
    <origin rpy="0 0 0" xyz="0.008100043308759242 -0.0015734171294430332 0.10401739320443494"/>
    <mass value="0.10302216766599791"/>
    <inertia ixx="0.000378" ixy="0.0" ixz="-0.0" iyy="0.000397" iyz="0.0" izz="3.3e-05"/>
  </inertial>
  <visual>
    <origin rpy="0 0 0" xyz="-0.690018 0.369334 0.01"/>
    <geometry>
      <mesh filename="package://nanny_description/meshes/extrude_4.stl" scale="0.001 0.001 0.001"/>
    </geometry>
    <material name="silver"/>
  </visual>
  <collision>
    <origin rpy="0 0 0" xyz="-0.690018 0.369334 0.01"/>
    <geometry>
      <mesh filename="package://nanny_description/meshes/extrude_4.stl" scale="0.001 0.001 0.001"/>
    </geometry>
  </collision>
</link>

<link name="extrude_5">
  <inertial>
    <origin rpy="0 0 0" xyz="-0.0200702585732202 -0.001573523610051586 0.10401739320443444"/>
    <mass value="0.10302216766599791"/>
    <inertia ixx="0.000378" ixy="0.0" ixz="-0.0" iyy="0.000397" iyz="0.0" izz="3.3e-05"/>
  </inertial>
  <visual>
    <origin rpy="0 0 0" xyz="-0.519747 -0.230753 0.01"/>
    <geometry>
      <mesh filename="package://nanny_description/meshes/extrude_5.stl" scale="0.001 0.001 0.001"/>
    </geometry>
    <material name="silver"/>
  </visual>
  <collision>
    <origin rpy="0 0 0" xyz="-0.519747 -0.230753 0.01"/>
    <geometry>
      <mesh filename="package://nanny_description/meshes/extrude_5.stl" scale="0.001 0.001 0.001"/>
    </geometry>
  </collision>
</link>

<link name="battery_v1_1">
  <inertial>
    <origin rpy="0 0 0" xyz="-0.17779995501708884 0.11429984542405569 0.05079989320443594"/>
    <mass value="9.072981380925"/>
    <inertia ixx="0.047316" ixy="-0.0" ixz="0.0" iyy="0.103412" iyz="-0.0" izz="0.135119"/>
  </inertial>
  <visual>
    <origin rpy="0 0 0" xyz="-0.674918 0.31791 0.01"/>
    <geometry>
      <mesh filename="package://nanny_description/meshes/battery_v1_1.stl" scale="0.001 0.001 0.001"/>
    </geometry>
    <material name="silver"/>
  </visual>
  <collision>
    <origin rpy="0 0 0" xyz="-0.674918 0.31791 0.01"/>
    <geometry>
      <mesh filename="package://nanny_description/meshes/battery_v1_1.stl" scale="0.001 0.001 0.001"/>
    </geometry>
  </collision>
</link>

<link name="bracket_v1_1">
  <inertial>
    <origin rpy="0 0 0" xyz="-0.0006279832134617469 0.06485509114929999 0.07514537258229421"/>
    <mass value="4.089659585571246"/>
    <inertia ixx="0.019505" ixy="0.0" ixz="-0.0" iyy="0.00638" iyz="1.2e-05" izz="0.014216"/>
  </inertial>
  <visual>
    <origin rpy="0 0 0" xyz="-0.181515 0.330913 0.01"/>
    <geometry>
      <mesh filename="package://nanny_description/meshes/bracket_v1_1.stl" scale="0.001 0.001 0.001"/>
    </geometry>
    <material name="silver"/>
  </visual>
  <collision>
    <origin rpy="0 0 0" xyz="-0.181515 0.330913 0.01"/>
    <geometry>
      <mesh filename="package://nanny_description/meshes/bracket_v1_1.stl" scale="0.001 0.001 0.001"/>
    </geometry>
  </collision>
</link>

<link name="bracket_v1__1__1">
  <inertial>
    <origin rpy="0 0 0" xyz="-0.0006288607920780231 0.06485509114934251 0.07514537258229424"/>
    <mass value="4.089659585571246"/>
    <inertia ixx="0.019505" ixy="0.0" ixz="-0.0" iyy="0.00638" iyz="1.2e-05" izz="0.014216"/>
  </inertial>
  <visual>
    <origin rpy="0 0 0" xyz="-0.818321 0.335913 0.01"/>
    <geometry>
      <mesh filename="package://nanny_description/meshes/bracket_v1__1__1.stl" scale="0.001 0.001 0.001"/>
    </geometry>
    <material name="silver"/>
  </visual>
  <collision>
    <origin rpy="0 0 0" xyz="-0.818321 0.335913 0.01"/>
    <geometry>
      <mesh filename="package://nanny_description/meshes/bracket_v1__1__1.stl" scale="0.001 0.001 0.001"/>
    </geometry>
  </collision>
</link>

<link name="universalplate_v1_1">
  <inertial>
    <origin rpy="0 0 0" xyz="0.1605893348499859 0.3200952825015396 0.0063498932044359635"/>
    <mass value="10.535008068288963"/>
    <inertia ixx="0.438684" ixy="-0.000175" ixz="0.0" iyy="0.454628" iyz="0.0" izz="0.893028"/>
  </inertial>
  <visual>
    <origin rpy="0 0 0" xyz="-0.339208 0.371284 -0.198035"/>
    <geometry>
      <mesh filename="package://nanny_description/meshes/universalplate_v1_1.stl" scale="0.001 0.001 0.001"/>
    </geometry>
    <material name="silver"/>
  </visual>
  <collision>
    <origin rpy="0 0 0" xyz="-0.339208 0.371284 -0.198035"/>
    <geometry>
      <mesh filename="package://nanny_description/meshes/universalplate_v1_1.stl" scale="0.001 0.001 0.001"/>
    </geometry>
  </collision>
</link>

<link name="castorconnect_v1_1">
  <inertial>
    <origin rpy="0 0 0" xyz="-2.6157613655652945e-07 0.012712389897948373 -0.03991053178347348"/>
    <mass value="0.7450704925069065"/>
    <inertia ixx="0.002151" ixy="-0.0" ixz="-0.0" iyy="0.001975" iyz="0.000571" izz="0.001293"/>
  </inertial>
  <visual>
    <origin rpy="0 0 0" xyz="-0.240208 -0.166116 -0.198035"/>
    <geometry>
      <mesh filename="package://nanny_description/meshes/castorconnect_v1_1.stl" scale="0.001 0.001 0.001"/>
    </geometry>
    <material name="silver"/>
  </visual>
  <collision>
    <origin rpy="0 0 0" xyz="-0.240208 -0.166116 -0.198035"/>
    <geometry>
      <mesh filename="package://nanny_description/meshes/castorconnect_v1_1.stl" scale="0.001 0.001 0.001"/>
    </geometry>
  </collision>
</link>

<link name="castorconnect_v1__1__1">
  <inertial>
    <origin rpy="0 0 0" xyz="-2.6157613552957315e-07 0.012712389897983678 -0.03991053178347348"/>
    <mass value="0.7450704925069065"/>
    <inertia ixx="0.002151" ixy="-0.0" ixz="-0.0" iyy="0.001975" iyz="0.000571" izz="0.001293"/>
  </inertial>
  <visual>
    <origin rpy="0 0 0" xyz="-0.759408 -0.166116 -0.198035"/>
    <geometry>
      <mesh filename="package://nanny_description/meshes/castorconnect_v1__1__1.stl" scale="0.001 0.001 0.001"/>
    </geometry>
    <material name="silver"/>
  </visual>
  <collision>
    <origin rpy="0 0 0" xyz="-0.759408 -0.166116 -0.198035"/>
    <geometry>
      <mesh filename="package://nanny_description/meshes/castorconnect_v1__1__1.stl" scale="0.001 0.001 0.001"/>
    </geometry>
  </collision>
</link>

<link name="castor_v1_1">
  <inertial>
    <origin rpy="0 0 0" xyz="-0.01270026238790986 -3.9525341968826844e-07 -1.0679556407267032e-07"/>
    <mass value="2.9032959895157067"/>
    <inertia ixx="0.015662" ixy="0.0" ixz="-0.0" iyy="0.008205" iyz="0.0" izz="0.008205"/>
  </inertial>
  <visual>
    <origin rpy="0 0 0" xyz="-0.253053 -0.228029 -0.058335"/>
    <geometry>
      <mesh filename="package://nanny_description/meshes/castor_v1_1.stl" scale="0.001 0.001 0.001"/>
    </geometry>
    <material name="silver"/>
  </visual>
  <collision>
    <origin rpy="0 0 0" xyz="-0.253053 -0.228029 -0.058335"/>
    <geometry>
      <mesh filename="package://nanny_description/meshes/castor_v1_1.stl" scale="0.001 0.001 0.001"/>
    </geometry>
  </collision>
</link>

<link name="castor_v1__1__1">
  <inertial>
    <origin rpy="0 0 0" xyz="0.012699737612091533 -3.952533863815777e-07 -1.0679556403103696e-07"/>
    <mass value="2.9032959895157067"/>
    <inertia ixx="0.015662" ixy="0.0" ixz="0.0" iyy="0.008205" iyz="0.0" izz="0.008205"/>
  </inertial>
  <visual>
    <origin rpy="0 0 0" xyz="-0.746563 -0.221679 -0.058335"/>
    <geometry>
      <mesh filename="package://nanny_description/meshes/castor_v1__1__1.stl" scale="0.001 0.001 0.001"/>
    </geometry>
    <material name="silver"/>
  </visual>
  <collision>
    <origin rpy="0 0 0" xyz="-0.746563 -0.221679 -0.058335"/>
    <geometry>
      <mesh filename="package://nanny_description/meshes/castor_v1__1__1.stl" scale="0.001 0.001 0.001"/>
    </geometry>
  </collision>
</link>

<link name="extrude2_1">
  <inertial>
    <origin rpy="0 0 0" xyz="-0.002890757990438919 0.00959061634807562 0.22851739320443554"/>
    <mass value="0.22633084047986823"/>
    <inertia ixx="0.003955" ixy="0.0" ixz="0.0" iyy="0.003997" iyz="0.0" izz="7.2e-05"/>
  </inertial>
  <visual>
    <origin rpy="0 0 0" xyz="-0.354708 0.380784 -0.210735"/>
    <geometry>
      <mesh filename="package://nanny_description/meshes/extrude2_1.stl" scale="0.001 0.001 0.001"/>
    </geometry>
    <material name="silver"/>
  </visual>
  <collision>
    <origin rpy="0 0 0" xyz="-0.354708 0.380784 -0.210735"/>
    <geometry>
      <mesh filename="package://nanny_description/meshes/extrude2_1.stl" scale="0.001 0.001 0.001"/>
    </geometry>
  </collision>
</link>

<link name="extrude2_2">
  <inertial>
    <origin rpy="0 0 0" xyz="-0.00810026071370551 0.0015739271981915492 0.22851739320443554"/>
    <mass value="0.22633084047986823"/>
    <inertia ixx="0.003955" ixy="0.0" ixz="-0.0" iyy="0.003997" iyz="0.0" izz="7.2e-05"/>
  </inertial>
  <visual>
    <origin rpy="0 0 0" xyz="-0.655908 0.372759 -0.210735"/>
    <geometry>
      <mesh filename="package://nanny_description/meshes/extrude2_2.stl" scale="0.001 0.001 0.001"/>
    </geometry>
    <material name="silver"/>
  </visual>
  <collision>
    <origin rpy="0 0 0" xyz="-0.655908 0.372759 -0.210735"/>
    <geometry>
      <mesh filename="package://nanny_description/meshes/extrude2_2.stl" scale="0.001 0.001 0.001"/>
    </geometry>
  </collision>
</link>

<link name="extrude2_3">
  <inertial>
    <origin rpy="0 0 0" xyz="-0.0015740028769496428 -0.016899893579216042 0.22851739320443565"/>
    <mass value="0.22633084047986823"/>
    <inertia ixx="0.003997" ixy="-0.0" ixz="0.0" iyy="0.003955" iyz="0.0" izz="7.2e-05"/>
  </inertial>
  <visual>
    <origin rpy="0 0 0" xyz="-0.831708 0.016584 -0.210735"/>
    <geometry>
      <mesh filename="package://nanny_description/meshes/extrude2_3.stl" scale="0.001 0.001 0.001"/>
    </geometry>
    <material name="silver"/>
  </visual>
  <collision>
    <origin rpy="0 0 0" xyz="-0.831708 0.016584 -0.210735"/>
    <geometry>
      <mesh filename="package://nanny_description/meshes/extrude2_3.stl" scale="0.001 0.001 0.001"/>
    </geometry>
  </collision>
</link>

<link name="extrude2_4">
  <inertial>
    <origin rpy="0 0 0" xyz="0.0015732968992555885 0.008100102021695171 0.22851739320443554"/>
    <mass value="0.22633084047986823"/>
    <inertia ixx="0.003997" ixy="-0.0" ixz="0.0" iyy="0.003955" iyz="0.0" izz="7.2e-05"/>
  </inertial>
  <visual>
    <origin rpy="0 0 0" xyz="-0.167723 0.041484 -0.210735"/>
    <geometry>
      <mesh filename="package://nanny_description/meshes/extrude2_4.stl" scale="0.001 0.001 0.001"/>
    </geometry>
    <material name="silver"/>
  </visual>
  <collision>
    <origin rpy="0 0 0" xyz="-0.167723 0.041484 -0.210735"/>
    <geometry>
      <mesh filename="package://nanny_description/meshes/extrude2_4.stl" scale="0.001 0.001 0.001"/>
    </geometry>
  </collision>
</link>

<link name="extrude2_5">
  <inertial>
    <origin rpy="0 0 0" xyz="0.005510612840938678 -0.005475807193469073 0.22851739320443554"/>
    <mass value="0.22633084047986823"/>
    <inertia ixx="0.003955" ixy="0.0" ixz="0.0" iyy="0.003997" iyz="0.0" izz="7.2e-05"/>
  </inertial>
  <visual>
    <origin rpy="0 0 0" xyz="-0.346208 -0.234216 -0.210735"/>
    <geometry>
      <mesh filename="package://nanny_description/meshes/extrude2_5.stl" scale="0.001 0.001 0.001"/>
    </geometry>
    <material name="silver"/>
  </visual>
  <collision>
    <origin rpy="0 0 0" xyz="-0.346208 -0.234216 -0.210735"/>
    <geometry>
      <mesh filename="package://nanny_description/meshes/extrude2_5.stl" scale="0.001 0.001 0.001"/>
    </geometry>
  </collision>
</link>

<link name="extrude2_6">
  <inertial>
    <origin rpy="0 0 0" xyz="-0.01631552370564393 0.00532858224376756 0.22851739320443565"/>
    <mass value="0.22633084047986823"/>
    <inertia ixx="0.003955" ixy="0.0" ixz="-0.0" iyy="0.003997" iyz="-0.0" izz="7.2e-05"/>
  </inertial>
  <visual>
    <origin rpy="0 0 0" xyz="-0.664208 -0.223316 -0.210735"/>
    <geometry>
      <mesh filename="package://nanny_description/meshes/extrude2_6.stl" scale="0.001 0.001 0.001"/>
    </geometry>
    <material name="silver"/>
  </visual>
  <collision>
    <origin rpy="0 0 0" xyz="-0.664208 -0.223316 -0.210735"/>
    <geometry>
      <mesh filename="package://nanny_description/meshes/extrude2_6.stl" scale="0.001 0.001 0.001"/>
    </geometry>
  </collision>
</link>

<link name="universalplate_v1__1__1">
  <inertial>
    <origin rpy="0 0 0" xyz="0.16213352060787023 0.3193159061923979 0.006349893204436463"/>
    <mass value="10.535008068288963"/>
    <inertia ixx="0.438682" ixy="-9.8e-05" ixz="0.0" iyy="0.454629" iyz="0.0" izz="0.893028"/>
  </inertial>
  <visual>
    <origin rpy="0 0 0" xyz="-0.339287 0.371159 -0.66777"/>
    <geometry>
      <mesh filename="package://nanny_description/meshes/universalplate_v1__1__1.stl" scale="0.001 0.001 0.001"/>
    </geometry>
    <material name="silver"/>
  </visual>
  <collision>
    <origin rpy="0 0 0" xyz="-0.339287 0.371159 -0.66777"/>
    <geometry>
      <mesh filename="package://nanny_description/meshes/universalplate_v1__1__1.stl" scale="0.001 0.001 0.001"/>
    </geometry>
  </collision>
</link>

<link name="extrude3_1">
  <inertial>
    <origin rpy="0 0 0" xyz="0.007057659000020422 0.006954919789942726 0.2285173932044362"/>
    <mass value="0.22633084047986823"/>
    <inertia ixx="0.003955" ixy="0.0" ixz="0.0" iyy="0.003997" iyz="0.0" izz="7.2e-05"/>
  </inertial>
  <visual>
    <origin rpy="0 0 0" xyz="-0.294756 0.377544 -0.68047"/>
    <geometry>
      <mesh filename="package://nanny_description/meshes/extrude3_1.stl" scale="0.001 0.001 0.001"/>
    </geometry>
    <material name="silver"/>
  </visual>
  <collision>
    <origin rpy="0 0 0" xyz="-0.294756 0.377544 -0.68047"/>
    <geometry>
      <mesh filename="package://nanny_description/meshes/extrude3_1.stl" scale="0.001 0.001 0.001"/>
    </geometry>
  </collision>
</link>

<link name="extrude3_2">
  <inertial>
    <origin rpy="0 0 0" xyz="-0.008092713005139363 0.0016131311036912122 0.2285173932044362"/>
    <mass value="0.22633084047986823"/>
    <inertia ixx="0.003955" ixy="0.0" ixz="0.0" iyy="0.003997" iyz="-0.0" izz="7.2e-05"/>
  </inertial>
  <visual>
    <origin rpy="0 0 0" xyz="-0.705977 0.374254 -0.68047"/>
    <geometry>
      <mesh filename="package://nanny_description/meshes/extrude3_2.stl" scale="0.001 0.001 0.001"/>
    </geometry>
    <material name="silver"/>
  </visual>
  <collision>
    <origin rpy="0 0 0" xyz="-0.705977 0.374254 -0.68047"/>
    <geometry>
      <mesh filename="package://nanny_description/meshes/extrude3_2.stl" scale="0.001 0.001 0.001"/>
    </geometry>
  </collision>
</link>

<link name="extrude3_3">
  <inertial>
    <origin rpy="0 0 0" xyz="-0.004346858320038893 0.010947064989827213 0.22851739320443643"/>
    <mass value="0.22633084047986823"/>
    <inertia ixx="0.003997" ixy="-0.0" ixz="0.0" iyy="0.003955" iyz="0.0" izz="7.2e-05"/>
  </inertial>
  <visual>
    <origin rpy="0 0 0" xyz="-0.836218 0.096679 -0.68047"/>
    <geometry>
      <mesh filename="package://nanny_description/meshes/extrude3_3.stl" scale="0.001 0.001 0.001"/>
    </geometry>
    <material name="silver"/>
  </visual>
  <collision>
    <origin rpy="0 0 0" xyz="-0.836218 0.096679 -0.68047"/>
    <geometry>
      <mesh filename="package://nanny_description/meshes/extrude3_3.stl" scale="0.001 0.001 0.001"/>
    </geometry>
  </collision>
</link>

<link name="extrude3_4">
  <inertial>
    <origin rpy="0 0 0" xyz="-0.022948659361198276 0.010611331367616772 0.22851739320443476"/>
    <mass value="0.22633084047986823"/>
    <inertia ixx="0.003955" ixy="0.0" ixz="0.0" iyy="0.003997" iyz="0.0" izz="7.2e-05"/>
  </inertial>
  <visual>
    <origin rpy="0 0 0" xyz="-0.718816 -0.216805 -0.68047"/>
    <geometry>
      <mesh filename="package://nanny_description/meshes/extrude3_4.stl" scale="0.001 0.001 0.001"/>
    </geometry>
    <material name="silver"/>
  </visual>
  <collision>
    <origin rpy="0 0 0" xyz="-0.718816 -0.216805 -0.68047"/>
    <geometry>
      <mesh filename="package://nanny_description/meshes/extrude3_4.stl" scale="0.001 0.001 0.001"/>
    </geometry>
  </collision>
</link>

<link name="extrude3_5">
  <inertial>
    <origin rpy="0 0 0" xyz="0.0016125120246620883 0.008092360390156803 0.22851739320443554"/>
    <mass value="0.22633084047986823"/>
    <inertia ixx="0.003997" ixy="-0.0" ixz="-0.0" iyy="0.003955" iyz="-0.0" izz="7.2e-05"/>
  </inertial>
  <visual>
    <origin rpy="0 0 0" xyz="-0.169055 0.090614 -0.68047"/>
    <geometry>
      <mesh filename="package://nanny_description/meshes/extrude3_5.stl" scale="0.001 0.001 0.001"/>
    </geometry>
    <material name="silver"/>
  </visual>
  <collision>
    <origin rpy="0 0 0" xyz="-0.169055 0.090614 -0.68047"/>
    <geometry>
      <mesh filename="package://nanny_description/meshes/extrude3_5.stl" scale="0.001 0.001 0.001"/>
    </geometry>
  </collision>
</link>

<link name="extrude3_6">
  <inertial>
    <origin rpy="0 0 0" xyz="-0.007153044335591385 0.003850087755044612 0.22851739320443576"/>
    <mass value="0.22633084047986823"/>
    <inertia ixx="0.003955" ixy="0.0" ixz="-0.0" iyy="0.003997" iyz="0.0" izz="7.2e-05"/>
  </inertial>
  <visual>
    <origin rpy="0 0 0" xyz="-0.309164 -0.224709 -0.68047"/>
    <geometry>
      <mesh filename="package://nanny_description/meshes/extrude3_6.stl" scale="0.001 0.001 0.001"/>
    </geometry>
    <material name="silver"/>
  </visual>
  <collision>
    <origin rpy="0 0 0" xyz="-0.309164 -0.224709 -0.68047"/>
    <geometry>
      <mesh filename="package://nanny_description/meshes/extrude3_6.stl" scale="0.001 0.001 0.001"/>
    </geometry>
  </collision>
</link>

<link name="universalplate_v1__2__1">
  <inertial>
    <origin rpy="0 0 0" xyz="0.16213319504084872 0.31931566568776937 0.006349893204437018"/>
    <mass value="10.535008068288963"/>
    <inertia ixx="0.438682" ixy="-9.8e-05" ixz="0.0" iyy="0.454629" iyz="-0.0" izz="0.893028"/>
  </inertial>
  <visual>
    <origin rpy="0 0 0" xyz="-0.339211 0.371243 -1.13751"/>
    <geometry>
      <mesh filename="package://nanny_description/meshes/universalplate_v1__2__1.stl" scale="0.001 0.001 0.001"/>
    </geometry>
    <material name="silver"/>
  </visual>
  <collision>
    <origin rpy="0 0 0" xyz="-0.339211 0.371243 -1.13751"/>
    <geometry>
      <mesh filename="package://nanny_description/meshes/universalplate_v1__2__1.stl" scale="0.001 0.001 0.001"/>
    </geometry>
  </collision>
</link>

<link name="extrude3__1__1">
  <inertial>
    <origin rpy="0 0 0" xyz="-0.02294895351263415 0.01061053896639691 0.41901739320443676"/>
    <mass value="0.4150079663516937"/>
    <inertia ixx="0.024316" ixy="0.0" ixz="-0.0" iyy="0.024393" iyz="-0.0" izz="0.000132"/>
  </inertial>
  <visual>
    <origin rpy="0 0 0" xyz="-0.374645 0.382024 -1.15021"/>
    <geometry>
      <mesh filename="package://nanny_description/meshes/extrude3__1__1.stl" scale="0.001 0.001 0.001"/>
    </geometry>
    <material name="silver"/>
  </visual>
  <collision>
    <origin rpy="0 0 0" xyz="-0.374645 0.382024 -1.15021"/>
    <geometry>
      <mesh filename="package://nanny_description/meshes/extrude3__1__1.stl" scale="0.001 0.001 0.001"/>
    </geometry>
  </collision>
</link>

<link name="extrude3__1__2">
  <inertial>
    <origin rpy="0 0 0" xyz="-0.010904807975125386 0.004452819988318535 0.41901739320443676"/>
    <mass value="0.4150079663516937"/>
    <inertia ixx="0.024316" ixy="0.0" ixz="-0.0" iyy="0.024393" iyz="-0.0" izz="0.000132"/>
  </inertial>
  <visual>
    <origin rpy="0 0 0" xyz="-0.658886 0.377162 -1.15021"/>
    <geometry>
      <mesh filename="package://nanny_description/meshes/extrude3__1__2.stl" scale="0.001 0.001 0.001"/>
    </geometry>
    <material name="silver"/>
  </visual>
  <collision>
    <origin rpy="0 0 0" xyz="-0.658886 0.377162 -1.15021"/>
    <geometry>
      <mesh filename="package://nanny_description/meshes/extrude3__1__2.stl" scale="0.001 0.001 0.001"/>
    </geometry>
  </collision>
</link>

<link name="extrude3__1__3">
  <inertial>
    <origin rpy="0 0 0" xyz="-0.0016126785482952766 -0.00809226097769293 0.41901739320443676"/>
    <mass value="0.4150079663516937"/>
    <inertia ixx="0.024393" ixy="-0.0" ixz="-0.0" iyy="0.024316" iyz="-0.0" izz="0.000132"/>
  </inertial>
  <visual>
    <origin rpy="0 0 0" xyz="-0.83349 0.027726 -1.15021"/>
    <geometry>
      <mesh filename="package://nanny_description/meshes/extrude3__1__3.stl" scale="0.001 0.001 0.001"/>
    </geometry>
    <material name="silver"/>
  </visual>
  <collision>
    <origin rpy="0 0 0" xyz="-0.83349 0.027726 -1.15021"/>
    <geometry>
      <mesh filename="package://nanny_description/meshes/extrude3__1__3.stl" scale="0.001 0.001 0.001"/>
    </geometry>
  </collision>
</link>

<link name="extrude3__1__4">
  <inertial>
    <origin rpy="0 0 0" xyz="0.001655012074481016 0.016892059023513047 0.41901739320443676"/>
    <mass value="0.4150079663516937"/>
    <inertia ixx="0.024393" ixy="-0.0" ixz="-0.0" iyy="0.024316" iyz="-0.0" izz="0.000132"/>
  </inertial>
  <visual>
    <origin rpy="0 0 0" xyz="-0.169277 0.049619 -1.15021"/>
    <geometry>
      <mesh filename="package://nanny_description/meshes/extrude3__1__4.stl" scale="0.001 0.001 0.001"/>
    </geometry>
    <material name="silver"/>
  </visual>
  <collision>
    <origin rpy="0 0 0" xyz="-0.169277 0.049619 -1.15021"/>
    <geometry>
      <mesh filename="package://nanny_description/meshes/extrude3__1__4.stl" scale="0.001 0.001 0.001"/>
    </geometry>
  </collision>
</link>

<link name="extrude3__1__5">
  <inertial>
    <origin rpy="0 0 0" xyz="0.014052568231956886 -0.004468268786168045 0.4190173932044359"/>
    <mass value="0.4150079663516937"/>
    <inertia ixx="0.024316" ixy="0.0" ixz="-0.0" iyy="0.024393" iyz="-0.0" izz="0.000132"/>
  </inertial>
  <visual>
    <origin rpy="0 0 0" xyz="-0.636826 -0.231827 -1.15021"/>
    <geometry>
      <mesh filename="package://nanny_description/meshes/extrude3__1__5.stl" scale="0.001 0.001 0.001"/>
    </geometry>
    <material name="silver"/>
  </visual>
  <collision>
    <origin rpy="0 0 0" xyz="-0.636826 -0.231827 -1.15021"/>
    <geometry>
      <mesh filename="package://nanny_description/meshes/extrude3__1__5.stl" scale="0.001 0.001 0.001"/>
    </geometry>
  </collision>
</link>

<link name="extrude3__1__6">
  <inertial>
    <origin rpy="0 0 0" xyz="0.008099804448438885 -3.8750442625357095e-05 0.41901739320443654"/>
    <mass value="0.4150079663516937"/>
    <inertia ixx="0.024316" ixy="0.0" ixz="0.0" iyy="0.024393" iyz="0.0" izz="0.000132"/>
  </inertial>
  <visual>
    <origin rpy="0 0 0" xyz="-0.346508 -0.228728 -1.15021"/>
    <geometry>
      <mesh filename="package://nanny_description/meshes/extrude3__1__6.stl" scale="0.001 0.001 0.001"/>
    </geometry>
    <material name="silver"/>
  </visual>
  <collision>
    <origin rpy="0 0 0" xyz="-0.346508 -0.228728 -1.15021"/>
    <geometry>
      <mesh filename="package://nanny_description/meshes/extrude3__1__6.stl" scale="0.001 0.001 0.001"/>
    </geometry>
  </collision>
</link>

<link name="universalplate_v1__3__1">
  <inertial>
    <origin rpy="0 0 0" xyz="0.13713357837476375 0.3194372143564179 0.006349893204435908"/>
    <mass value="10.535008068288963"/>
    <inertia ixx="0.438682" ixy="-9.8e-05" ixz="0.0" iyy="0.454629" iyz="0.0" izz="0.893028"/>
  </inertial>
  <visual>
    <origin rpy="0 0 0" xyz="-0.364196 0.371448 -1.98824"/>
    <geometry>
      <mesh filename="package://nanny_description/meshes/universalplate_v1__3__1.stl" scale="0.001 0.001 0.001"/>
    </geometry>
    <material name="silver"/>
  </visual>
  <collision>
    <origin rpy="0 0 0" xyz="-0.364196 0.371448 -1.98824"/>
    <geometry>
      <mesh filename="package://nanny_description/meshes/universalplate_v1__3__1.stl" scale="0.001 0.001 0.001"/>
    </geometry>
  </collision>
</link>

<joint name="Rigid1" type="fixed">
  <origin rpy="0 0 0" xyz="0.144318 -0.27111 0.011978"/>
  <parent link="base_link"/>
  <child link="motor_v1__1__1"/>
</joint>

<joint name="Rigid2" type="fixed">
  <origin rpy="0 0 0" xyz="0.808518 -0.27111 0.011978"/>
  <parent link="base_link"/>
  <child link="motor_v1_1"/>
</joint>

<joint name="Rev3" type="continuous">
  <origin rpy="0 0 0" xyz="-0.0755 -0.000102 0.044669"/>
  <parent link="motor_v1__1__1"/>
  <child link="wheel_v1__1__1"/>
  <axis xyz="1.0 0.0 -0.0"/>
</joint>

<joint name="Rev4" type="continuous">
  <origin rpy="0 0 0" xyz="0.1225 0.000101 0.044669"/>
  <parent link="motor_v1_1"/>
  <child link="wheel_v1_1"/>
  <axis xyz="-1.0 -0.0 -0.0"/>
</joint>

<joint name="Rigid8" type="fixed">
  <origin rpy="0 0 0" xyz="0.826018 -0.094334 0.011978"/>
  <parent link="base_link"/>
  <child link="extrude_1"/>
</joint>

<joint name="Rigid9" type="fixed">
  <origin rpy="0 0 0" xyz="0.180818 -0.074834 0.011978"/>
  <parent link="base_link"/>
  <child link="extrude_2"/>
</joint>

<joint name="Rigid10" type="fixed">
  <origin rpy="0 0 0" xyz="0.321318 -0.379834 0.011978"/>
  <parent link="base_link"/>
  <child link="extrude_3"/>
</joint>

<joint name="Rigid11" type="fixed">
  <origin rpy="0 0 0" xyz="0.690018 -0.369334 0.011978"/>
  <parent link="base_link"/>
  <child link="extrude_4"/>
</joint>

<joint name="Rigid12" type="fixed">
  <origin rpy="0 0 0" xyz="0.519747 0.230753 0.011978"/>
  <parent link="base_link"/>
  <child link="extrude_5"/>
</joint>

<joint name="Rigid13" type="fixed">
  <origin rpy="0 0 0" xyz="0.674918 -0.31791 0.011978"/>
  <parent link="base_link"/>
  <child link="battery_v1_1"/>
</joint>

<joint name="Rigid14" type="fixed">
  <origin rpy="0 0 0" xyz="0.181515 -0.330913 0.011978"/>
  <parent link="base_link"/>
  <child link="bracket_v1_1"/>
</joint>

<joint name="Rigid15" type="fixed">
  <origin rpy="0 0 0" xyz="0.818321 -0.335913 0.011978"/>
  <parent link="base_link"/>
  <child link="bracket_v1__1__1"/>
</joint>

<joint name="Rigid18" type="fixed">
  <origin rpy="0 0 0" xyz="0.01789 0.00855 0.208035"/>
  <parent link="extrude_3"/>
  <child link="universalplate_v1_1"/>
</joint>

<joint name="Rigid19" type="fixed">
  <origin rpy="0 0 0" xyz="-0.099 0.5374 0.0"/>
  <parent link="universalplate_v1_1"/>
  <child link="castorconnect_v1_1"/>
</joint>

<joint name="Rigid20" type="fixed">
  <origin rpy="0 0 0" xyz="0.4202 0.5374 0.0"/>
  <parent link="universalplate_v1_1"/>
  <child link="castorconnect_v1__1__1"/>
</joint>

<joint name="Rev21" type="continuous">
  <origin rpy="0 0 0" xyz="0.012845 0.061913 -0.1397"/>
  <parent link="castorconnect_v1_1"/>
  <child link="castor_v1_1"/>
  <axis xyz="-1.0 -0.0 -0.0"/>
</joint>

<joint name="Rev22" type="continuous">
  <origin rpy="0 0 0" xyz="-0.012845 0.055563 -0.1397"/>
  <parent link="castorconnect_v1__1__1"/>
  <child link="castor_v1__1__1"/>
  <axis xyz="1.0 0.0 0.0"/>
</joint>

<joint name="Rigid23" type="fixed">
  <origin rpy="0 0 0" xyz="0.0155 -0.0095 0.0127"/>
  <parent link="universalplate_v1_1"/>
  <child link="extrude2_1"/>
</joint>

<joint name="Rigid24" type="fixed">
  <origin rpy="0 0 0" xyz="0.3167 -0.001475 0.0127"/>
  <parent link="universalplate_v1_1"/>
  <child link="extrude2_2"/>
</joint>

<joint name="Rigid25" type="fixed">
  <origin rpy="0 0 0" xyz="0.4925 0.3547 0.0127"/>
  <parent link="universalplate_v1_1"/>
  <child link="extrude2_3"/>
</joint>

<joint name="Rigid26" type="fixed">
  <origin rpy="0 0 0" xyz="-0.171485 0.3298 0.0127"/>
  <parent link="universalplate_v1_1"/>
  <child link="extrude2_4"/>
</joint>

<joint name="Rigid27" type="fixed">
  <origin rpy="0 0 0" xyz="0.007 0.6055 0.0127"/>
  <parent link="universalplate_v1_1"/>
  <child link="extrude2_5"/>
</joint>

<joint name="Rigid28" type="fixed">
  <origin rpy="0 0 0" xyz="0.325 0.5946 0.0127"/>
  <parent link="universalplate_v1_1"/>
  <child link="extrude2_6"/>
</joint>

<joint name="Rigid30" type="fixed">
  <origin rpy="0 0 0" xyz="-0.015421 0.009625 0.457035"/>
  <parent link="extrude2_1"/>
  <child link="universalplate_v1__1__1"/>
</joint>

<joint name="Rigid31" type="fixed">
  <origin rpy="0 0 0" xyz="-0.044531 -0.006385 0.0127"/>
  <parent link="universalplate_v1__1__1"/>
  <child link="extrude3_1"/>
</joint>

<joint name="Rigid32" type="fixed">
  <origin rpy="0 0 0" xyz="0.36669 -0.003095 0.0127"/>
  <parent link="universalplate_v1__1__1"/>
  <child link="extrude3_2"/>
</joint>

<joint name="Rigid33" type="fixed">
  <origin rpy="0 0 0" xyz="0.496931 0.27448 0.0127"/>
  <parent link="universalplate_v1__1__1"/>
  <child link="extrude3_3"/>
</joint>

<joint name="Rigid34" type="fixed">
  <origin rpy="0 0 0" xyz="0.379529 0.587964 0.0127"/>
  <parent link="universalplate_v1__1__1"/>
  <child link="extrude3_4"/>
</joint>

<joint name="Rigid35" type="fixed">
  <origin rpy="0 0 0" xyz="-0.170232 0.280545 0.0127"/>
  <parent link="universalplate_v1__1__1"/>
  <child link="extrude3_5"/>
</joint>

<joint name="Rigid36" type="fixed">
  <origin rpy="0 0 0" xyz="-0.030123 0.595868 0.0127"/>
  <parent link="universalplate_v1__1__1"/>
  <child link="extrude3_6"/>
</joint>

<joint name="Rigid37" type="fixed">
  <origin rpy="0 0 0" xyz="0.044455 0.006301 0.457035"/>
  <parent link="extrude3_1"/>
  <child link="universalplate_v1__2__1"/>
</joint>

<joint name="Rigid38" type="fixed">
  <origin rpy="0 0 0" xyz="0.035434 -0.010781 0.0127"/>
  <parent link="universalplate_v1__2__1"/>
  <child link="extrude3__1__1"/>
</joint>

<joint name="Rigid39" type="fixed">
  <origin rpy="0 0 0" xyz="0.319675 -0.005919 0.0127"/>
  <parent link="universalplate_v1__2__1"/>
  <child link="extrude3__1__2"/>
</joint>

<joint name="Rigid40" type="fixed">
  <origin rpy="0 0 0" xyz="0.494279 0.343517 0.0127"/>
  <parent link="universalplate_v1__2__1"/>
  <child link="extrude3__1__3"/>
</joint>

<joint name="Rigid41" type="fixed">
  <origin rpy="0 0 0" xyz="-0.169934 0.321624 0.0127"/>
  <parent link="universalplate_v1__2__1"/>
  <child link="extrude3__1__4"/>
</joint>

<joint name="Rigid42" type="fixed">
  <origin rpy="0 0 0" xyz="0.297615 0.60307 0.0127"/>
  <parent link="universalplate_v1__2__1"/>
  <child link="extrude3__1__5"/>
</joint>

<joint name="Rigid43" type="fixed">
  <origin rpy="0 0 0" xyz="0.007297 0.599971 0.0127"/>
  <parent link="universalplate_v1__2__1"/>
  <child link="extrude3__1__6"/>
</joint>

<joint name="Rigid45" type="fixed">
  <origin rpy="0 0 0" xyz="-0.010449 0.010576 0.838035"/>
  <parent link="extrude3__1__1"/>
  <child link="universalplate_v1__3__1"/>
</joint>

<!--camera-->
<link name="camera">
    <collision>
      <origin xyz="0 0 0" rpy="0 0 0.021978"/>
      <geometry>
        <box size="${cameraSize} ${cameraSize} ${cameraSize}"/>
      </geometry>
    </collision>

    <visual>
      <origin xyz="0 0 0" rpy="0 0 0.021978"/>
      <geometry>
        <box size="${cameraSize} ${cameraSize} ${cameraSize}"/>
      </geometry>
      <material name="green"/>
    </visual>

    <inertial>
      <mass value="${cameraMass}" />
      <origin xyz="0 0 0" rpy="0 0 -1.578022"/>
      <box_inertia m="${cameraMass}" x="${cameraSize}" y="${cameraSize}" z="${cameraSize}" />
      <inertia ixx="1e-6" ixy="0" ixz="0" iyy="1e-6" iyz="0" izz="1e-6" />
    </inertial>
  </link>

  <joint name="camera_joint" type="fixed">
    <axis xyz="0 1 0" />
    <origin xyz=".15 -.02 .015" rpy="0 0 -1.6"/>
    <parent link="universalplate_v1__1__1"/>
    <child link="camera"/>
  </joint>

 <!-- sensor --> 
  <joint name="laser_joint" type="fixed">
    <axis xyz="0 1 0" />
    <origin xyz=".165 .30 .07" rpy="0 0 0.02"/>
    <parent link="universalplate_v1__1__1"/>
    <child link="laser"/>
  </joint>
 
  <link name="laser">
    <collision>
      <origin xyz="0 0 0" rpy="0 0 0.021978"/>
      <geometry>
    <box size="0.1 0.1 0.1"/>
      </geometry>
    </collision>

    <visual>
      <origin xyz="0 0 0" rpy="0 0 0.021978"/>
      <geometry>
        <mesh filename="package://nanny_description/meshes/laser.dae"/>
      </geometry>
    </visual>

    <inertial>
      <mass value="1e-5" />
      <origin xyz="0 0 0" rpy="0 0 0"/>
      <inertia ixx="1e-6" ixy="0" ixz="0" iyy="1e-6" iyz="0" izz="1e-6" />
    </inertial>
  </link>

</robot>
